<?xml version='1.0' encoding='utf-8'?>
<mujoco model="thunder_v3_mujoco">
  <compiler angle="radian" />
  <option timestep="0.001" iterations="50" solver="PGS" gravity="0 0 -9.81">
    <flag frictionloss="enable" sensor="enable" />
  </option>
  <worldbody>
    <geom name="ground" type="plane" size="0 0 1" pos="0 0 0" quat="1 0 0 0" condim="1" conaffinity="15" rgba="0.2 0.3 0.4 1" />
    <body name="base_link" pos="0 0 0.55">
      <site name="imu" size="0.01" pos="0 0 0" quat="1 0 0 0" />
      <inertial pos="-0.000838877 0.00711738 0.0765547" quat="0.54586 0.445843 0.55522 0.441579" mass="18.8369" diaginertia="0.647112 0.602654 0.248431" />
      <joint name="floating_base_joint" type="free" />
      <geom size="0.205 0.129 0.0775" pos="0 0.00124 0.07541" type="box" rgba="0.752941 0.752941 0.752941 1" />
      <geom size="0.025 0.135 0.07" pos="0.23 0 0.07" type="box" rgba="0.752941 0.752941 0.752941 1" />
      <geom size="0.025 0.135 0.07" pos="-0.23 0 0.07" type="box" rgba="0.752941 0.752941 0.752941 1" />
      <geom size="0.08 0.06 0.072" pos="0.335 0 0.08" type="box" rgba="0.752941 0.752941 0.752941 1" />
      <geom size="0.0825 0.05 0.075" pos="-0.3375 0 0.08" type="box" rgba="0.752941 0.752941 0.752941 1" />
      <geom size="0.0384 0.0384 0.04005" pos="-0.29638 -0.0012453 0.1849" quat="-3.67321e-06 0 0 1" type="box" rgba="0.898039 0.917647 0.929412 1" />
      <body name="FR_hip" pos="0.2395 -0.065 0.08065">
        <inertial pos="0.06964 -0.04836 0.00073" quat="0.625515 0.616922 0.338061 0.337421" mass="1.78126" diaginertia="0.0173549 0.0163714 0.00282375" />
        <joint name="FR_hip_joint" pos="0 0 0" axis="-1 0 0" range="-0.4 0.4" actuatorfrcrange="-120 120" />
        <geom size="0.06 0.024" pos="0.07752 -0.05564 0.00083" quat="0.707105 0.707108 0 0" type="cylinder" rgba="0.898039 0.917647 0.929412 1" />
        <body name="FR_thigh" pos="0.078 -0.0795 0">
          <inertial pos="-0.19519 -0.02855 -0.01131" quat="0.4815 0.451865 0.516848 0.544833" mass="2.40982" diaginertia="0.12237 0.120515 0.00342445" />
          <joint name="FR_thigh_joint" pos="0 0 0" axis="0 1 0" range="-3.14 0" actuatorfrcrange="-120 120" />
          <geom size="0.064 0.015" pos="0 -0.0195 0" quat="0.707105 0.707108 0 0" type="cylinder" rgba="0.898039 0.917647 0.929412 1" />
          <geom size="0.09 0.015 0.03" pos="-0.125 -0.02059 -0.01001" quat="0.997888 0 -0.0649542 0" type="box" rgba="0.898039 0.917647 0.929412 1" />
          <geom size="0.0655 0.028" pos="-0.2485 -0.032 -0.0135" quat="0.707105 0.707108 0 0" type="cylinder" rgba="0.898039 0.917647 0.929412 1" />
          <body name="FR_calf" pos="-0.24954 -0.057 -0.01515">
            <inertial pos="0.17379 -0.02895 0.03734" quat="0.576479 0.481443 0.405075 0.521344" mass="1.89384" diaginertia="0.0857584 0.084918 0.00239355" />
            <joint name="FR_calf_joint" pos="0 0 0" axis="0 1 0" range="0 3.14" actuatorfrcrange="-120 120" />
            <geom size="0.0635 0.015" pos="0 -0.02653 0" quat="0.707105 0.707108 0 0" type="cylinder" rgba="0.898039 0.917647 0.929412 1" />
            <geom size="0.09 0.02 0.0225" pos="0.14 -0.02903 0.0305" quat="0.991445 0 -0.130526 0" type="box" rgba="0.898039 0.917647 0.929412 1" />
            <geom size="0.06 0.0275" pos="0.249 -0.02903 0.0531" quat="0.707105 0.707108 0 0" type="cylinder" rgba="0.898039 0.917647 0.929412 1" />
            <body name="FR_foot" pos="0.24443 -0.061 0.0525">
              <inertial pos="0 -0.01385 0" quat="0.707107 0 0 0.707107" mass="1.40377" diaginertia="0.00121 0.00092 0.00092" />
              <joint name="FR_foot_joint" pos="0 0 0" axis="0 1 0" limited="false" actuatorfrcrange="-60 60" />
              <geom size="0.12 0.028085" pos="0 -0.01631 0" quat="0.707105 0.707108 0 0" type="cylinder" rgba="0.898039 0.917647 0.929412 1" />
            </body>
          </body>
        </body>
      </body>
      <body name="FL_hip" pos="0.2395 0.065 0.08065">
        <inertial pos="0.06964 0.04836 -0.00073" quat="0.338061 0.337421 0.625515 0.616922" mass="1.78126" diaginertia="0.0173549 0.0163714 0.00282375" />
        <joint name="FL_hip_joint" pos="0 0 0" axis="-1 0 0" range="-0.4 0.4" actuatorfrcrange="-120 120" />
        <geom size="0.06 0.024" pos="0.07752 0.05564 0.00083" quat="0.707105 0.707108 0 0" type="cylinder" rgba="0.898039 0.917647 0.929412 1" />
        <body name="FL_thigh" pos="0.078 0.0795 0">
          <inertial pos="-0.19484 0.02855 -0.01176" quat="0.542469 0.519007 0.447927 0.48551" mass="2.40982" diaginertia="0.121966 0.120079 0.00347509" />
          <joint name="FL_thigh_joint" pos="0 0 0" axis="0 -1 0" range="0 3.14" actuatorfrcrange="-120 120" />
          <geom size="0.064 0.015" pos="0 0.0195 0" quat="0.707105 0.707108 0 0" type="cylinder" rgba="0.898039 0.917647 0.929412 1" />
          <geom size="0.09 0.015 0.03" pos="-0.125 0.02059 -0.01001" quat="0.997888 0 -0.0649542 0" type="box" rgba="0.898039 0.917647 0.929412 1" />
          <geom size="0.0655 0.028" pos="-0.2485 0.032 -0.0135" quat="0.707105 0.707108 0 0" type="cylinder" rgba="0.898039 0.917647 0.929412 1" />
          <body name="FL_calf" pos="-0.24954 0.057 -0.01515">
            <inertial pos="0.17384 0.02895 0.03735" quat="0.52142 0.405052 0.481468 0.576405" mass="1.89384" diaginertia="0.0858075 0.0849699 0.00239256" />
            <joint name="FL_calf_joint" pos="0 0 0" axis="0 -1 0" range="-3.14 0" actuatorfrcrange="-120 120" />
            <geom size="0.0635 0.015" pos="0 0.02653 0" quat="0.707105 0.707108 0 0" type="cylinder" rgba="0.898039 0.917647 0.929412 1" />
            <geom size="0.09 0.02 0.0225" pos="0.14 0.02903 0.0305" quat="0.991445 0 -0.130526 0" type="box" rgba="0.898039 0.917647 0.929412 1" />
            <geom size="0.06 0.0275" pos="0.249 0.02903 0.0531" quat="0.707105 0.707108 0 0" type="cylinder" rgba="0.898039 0.917647 0.929412 1" />
            <body name="FL_foot" pos="0.24443 0.061 0.0525">
              <inertial pos="0 0.01385 0" quat="0.707107 0 0 0.707107" mass="1.40377" diaginertia="0.00121 0.00092 0.00092" />
              <joint name="FL_foot_joint" pos="0 0 0" axis="0 -1 0" limited="false" actuatorfrcrange="-60 60" />
              <geom size="0.12 0.028085" pos="0 0.01631 0" quat="0.707105 0.707108 0 0" type="cylinder" rgba="0.898039 0.917647 0.929412 1" />
            </body>
          </body>
        </body>
      </body>
      <body name="RR_hip" pos="-0.2395 -0.065 0.08065">
        <inertial pos="-0.06964 -0.04836 -0.00073" quat="0.337421 0.338061 0.616922 0.625515" mass="1.78126" diaginertia="0.0173549 0.0163714 0.00282375" />
        <joint name="RR_hip_joint" pos="0 0 0" axis="1 0 0" range="-0.4 0.4" actuatorfrcrange="-120 120" />
        <geom size="0.06 0.024" pos="-0.07752 -0.05564 0.00083" quat="0.707105 0.707108 0 0" type="cylinder" rgba="0.898039 0.917647 0.929412 1" />
        <body name="RR_thigh" pos="-0.078 -0.0795 0">
          <inertial pos="0.19483 -0.02855 -0.01178" quat="0.518661 0.542837 0.485186 0.448234" mass="2.40982" diaginertia="0.121966 0.120081 0.00347271" />
          <joint name="RR_thigh_joint" pos="0 0 0" axis="0 1 0" range="0 3.14" actuatorfrcrange="-120 120" />
          <geom size="0.064 0.015" pos="0 -0.0195 0" quat="0.707105 0.707108 0 0" type="cylinder" rgba="0.898039 0.917647 0.929412 1" />
          <geom size="0.09 0.015 0.03" pos="0.125 -0.02059 -0.01001" quat="0.997888 0 0.0649542 0" type="box" rgba="0.898039 0.917647 0.929412 1" />
          <geom size="0.0655 0.028" pos="0.2485 -0.032 -0.0135" quat="0.707105 0.707108 0 0" type="cylinder" rgba="0.898039 0.917647 0.929412 1" />
          <body name="RR_calf" pos="0.24954 -0.057 -0.01515">
            <inertial pos="-0.17384 -0.02895 0.03735" quat="0.405052 0.52142 0.576405 0.481468" mass="1.89384" diaginertia="0.0858075 0.0849699 0.00239256" />
            <joint name="RR_calf_joint" pos="0 0 0" axis="0 1 0" range="-3.14 3.14" actuatorfrcrange="-120 120" />
            <geom size="0.0635 0.015" pos="0 -0.02653 0" quat="0.707105 0.707108 0 0" type="cylinder" rgba="0.898039 0.917647 0.929412 1" />
            <geom size="0.09 0.02 0.0225" pos="-0.14 -0.02903 0.0305" quat="0.991445 0 0.130526 0" type="box" rgba="0.898039 0.917647 0.929412 1" />
            <geom size="0.06 0.0275" pos="-0.249 -0.02903 0.0531" quat="0.707105 0.707108 0 0" type="cylinder" rgba="0.898039 0.917647 0.929412 1" />
            <body name="RR_foot" pos="-0.24443 -0.061 0.0525">
              <inertial pos="0 -0.01385 0" quat="0.707107 0 0 0.707107" mass="1.40377" diaginertia="0.00121 0.00092 0.00092" />
              <joint name="RR_foot_joint" pos="0 0 0" axis="0 1 0" limited="false" actuatorfrcrange="-60 60" />
              <geom size="0.12 0.028085" pos="0 -0.01631 0" quat="0.707105 0.707108 0 0" type="cylinder" rgba="0.898039 0.917647 0.929412 1" />
            </body>
          </body>
        </body>
      </body>
      <body name="RL_hip" pos="-0.2395 0.065 0.08065">
        <inertial pos="-0.0696 0.04836 0.00075" quat="0.616925 0.625523 0.337421 0.338041" mass="1.78126" diaginertia="0.0173387 0.0163514 0.00282991" />
        <joint name="RL_hip_joint" pos="0 0 0" axis="1 0 0" range="-0.4 0.4" actuatorfrcrange="-120 120" />
        <geom size="0.06 0.024" pos="-0.07752 0.05564 0.00083" quat="0.707105 0.707108 0 0" type="cylinder" rgba="0.898039 0.917647 0.929412 1" />
        <body name="RL_thigh" pos="-0.078 0.0795 0">
          <inertial pos="0.19519 0.02855 -0.01131" quat="0.451865 0.4815 0.544833 0.516848" mass="2.40982" diaginertia="0.12237 0.120515 0.00342445" />
          <joint name="RL_thigh_joint" pos="0 0 0" axis="0 -1 0" range="-3.14 0" actuatorfrcrange="-120 120" />
          <geom size="0.064 0.015" pos="0 0.0195 0" quat="0.707105 0.707108 0 0" type="cylinder" rgba="0.898039 0.917647 0.929412 1" />
          <geom size="0.09 0.015 0.03" pos="0.125 0.02059 -0.01001" quat="0.997888 0 0.0649542 0" type="box" rgba="0.898039 0.917647 0.929412 1" />
          <geom size="0.0655 0.028" pos="0.2485 0.032 -0.0135" quat="0.707105 0.707108 0 0" type="cylinder" rgba="0.898039 0.917647 0.929412 1" />
          <body name="RL_calf" pos="0.24954 0.057 -0.01515">
            <inertial pos="-0.17385 0.02895 0.03733" quat="0.478974 0.57966 0.517737 0.408077" mass="1.89384" diaginertia="0.0858096 0.0849658 0.00239458" />
            <joint name="RL_calf_joint" pos="0 0 0" axis="0 -1 0" range="-3.14 3.14" actuatorfrcrange="-120 120" />
            <geom size="0.0635 0.015" pos="0 0.02653 0" quat="0.707105 0.707108 0 0" type="cylinder" rgba="0.898039 0.917647 0.929412 1" />
            <geom size="0.09 0.02 0.0225" pos="-0.14 0.02903 0.0305" quat="0.991445 0 0.130526 0" type="box" rgba="0.898039 0.917647 0.929412 1" />
            <geom size="0.06 0.0275" pos="-0.249 0.02903 0.0531" quat="0.707105 0.707108 0 0" type="cylinder" rgba="0.898039 0.917647 0.929412 1" />
            <body name="RL_foot" pos="-0.24443 0.061 0.0525">
              <inertial pos="0 0.01385 0" quat="0.707107 0 0 0.707107" mass="1.40377" diaginertia="0.00121 0.00092 0.00092" />
              <joint name="RL_foot_joint" pos="0 0 0" axis="0 -1 0" limited="false" actuatorfrcrange="-60 60" />
              <geom size="0.12 0.028085" pos="0 0.01631 0" quat="0.707105 0.707108 0 0" type="cylinder" rgba="0.898039 0.917647 0.929412 1" />
            </body>
          </body>
        </body>
      </body>
    </body>
  </worldbody>
  <actuator>
    <motor name="FR_hip_joint" joint="FR_hip_joint" gear="1" ctrllimited="true" ctrlrange="-120 120" />
    <motor name="FR_thigh_joint" joint="FR_thigh_joint" gear="1" ctrllimited="true" ctrlrange="-120 120" />
    <motor name="FR_calf_joint" joint="FR_calf_joint" gear="1" ctrllimited="true" ctrlrange="-120 120" />
    <motor name="FL_hip_joint" joint="FL_hip_joint" gear="1" ctrllimited="true" ctrlrange="-120 120" />
    <motor name="FL_thigh_joint" joint="FL_thigh_joint" gear="1" ctrllimited="true" ctrlrange="-120 120" />
    <motor name="FL_calf_joint" joint="FL_calf_joint" gear="1" ctrllimited="true" ctrlrange="-120 120" />
    <motor name="RR_hip_joint" joint="RR_hip_joint" gear="1" ctrllimited="true" ctrlrange="-120 120" />
    <motor name="RR_thigh_joint" joint="RR_thigh_joint" gear="1" ctrllimited="true" ctrlrange="-120 120" />
    <motor name="RR_calf_joint" joint="RR_calf_joint" gear="1" ctrllimited="true" ctrlrange="-120 120" />
    <motor name="RL_hip_joint" joint="RL_hip_joint" gear="1" ctrllimited="true" ctrlrange="-120 120" />
    <motor name="RL_thigh_joint" joint="RL_thigh_joint" gear="1" ctrllimited="true" ctrlrange="-120 120" />
    <motor name="RL_calf_joint" joint="RL_calf_joint" gear="1" ctrllimited="true" ctrlrange="-120 120" />
    <motor name="FR_foot_joint" joint="FR_foot_joint" gear="1" ctrllimited="true" ctrlrange="-60 60" />
    <motor name="FL_foot_joint" joint="FL_foot_joint" gear="1" ctrllimited="true" ctrlrange="-60 60" />
    <motor name="RR_foot_joint" joint="RR_foot_joint" gear="1" ctrllimited="true" ctrlrange="-60 60" />
    <motor name="RL_foot_joint" joint="RL_foot_joint" gear="1" ctrllimited="true" ctrlrange="-60 60" />
  </actuator>
  <sensor>
    <framequat name="orientation" objtype="site" noise="0.001" objname="imu" />
    <framepos name="position" objtype="site" noise="0.001" objname="imu" />
    <gyro name="angular-velocity" site="imu" noise="0.005" cutoff="34.9" />
    <velocimeter name="linear-velocity" site="imu" noise="0.001" cutoff="30" />
    <accelerometer name="linear-acceleration" site="imu" noise="0.005" cutoff="157" />
    <magnetometer name="magnetometer" site="imu" />
  </sensor>
</mujoco>