<?xml version='1.0' encoding='utf-8'?>
<robot name="wheeled_legged_dog_v3">
  <link name="base_link">
    <inertial>
      <origin xyz="-0.00111 0.00718 0.07632" rpy="0 0 0" />
      <mass value="18.69147" />
      <inertia ixx="0.24077" ixy="-0.00158" ixz="0.00277" iyy="0.63159" iyz="-0.00895" izz="0.58481" />
    </inertial>
    <visual>
      <origin xyz="0 0 0" rpy="0 0 0" />
      <geometry>
        <mesh filename="../meshes/base_link.STL" />
      </geometry>
      <material name="">
        <color rgba="0.752941176470588 0.752941176470588 0.752941176470588 1" />
      </material>
    </visual>
    <collision>
      <origin xyz="0 0.00124 0.07541" rpy="0 0 0" />
      <geometry>
        <box size="0.41 0.258 0.155" />
      </geometry>
    </collision>
    <collision>
      <origin xyz="0.23 0 0.07" rpy="0 0 0" />
      <geometry>
        <box size="0.05 0.27 0.14" />
      </geometry>
    </collision>
    <collision>
      <origin xyz="-0.23 0 0.07" rpy="0 0 0" />
      <geometry>
        <box size="0.05 0.27 0.14" />
      </geometry>
    </collision>
    <collision>
      <origin xyz="0.335 0 0.08" rpy="0 0 0" />
      <geometry>
        <box size="0.16 0.12 0.144" />
      </geometry>
    </collision>
    <collision>
      <origin xyz="-0.3375 0 0.08" rpy="0 0 0" />
      <geometry>
        <box size="0.165 0.10 0.15" />
      </geometry>
    </collision>
  </link>

  <link name="fr_hip_Link">
    <inertial>
      <origin xyz="0.06964 -0.04836 0.00073" rpy="0 0 0" />
      <mass value="1.78126" />
      <inertia ixx="0.00712" ixy="0.00663" ixz="-0.00012" iyy="0.01306" iyz="0.00007" izz="0.01637" />
    </inertial>
    <visual>
      <origin xyz="0 0 0" rpy="0 0 0" />
      <geometry>
        <mesh filename="../meshes/fr_hip_Link.STL" />
      </geometry>
      <material name="">
        <color rgba="0.898039215686275 0.917647058823529 0.929411764705882 1" />
      </material>
    </visual>
    <collision>
      <origin xyz="0.07752 -0.05564 0.00083" rpy="1.5708 0 0" />
      <geometry>
        <cylinder radius="0.06" length="0.048" />
      </geometry>
    </collision>
  </link>
  <joint name="fr_hip_joint" type="revolute">
    <origin xyz="0.2395 -0.065 0.08065" rpy="0 0 0" />
    <parent link="base_link" />
    <child link="fr_hip_Link" />
    <axis xyz="-1 0 0" />
    <limit lower="-0.41" upper="0.41" effort="0" velocity="0" />
  </joint>
  <link name="fr_thigh_Link">
    <inertial>
      <origin xyz="-0.19519 -0.02855 -0.01131" rpy="0 0 0" />
      <mass value="2.40982" />
      <inertia ixx="0.00576" ixy="-0.01508" ixz="-0.00665" iyy="0.12042" iyz="-0.00087" izz="0.12013" />
    </inertial>
    <visual>
      <origin xyz="0 0 0" rpy="0 0 0" />
      <geometry>
        <mesh filename="../meshes/fr_thigh_Link.STL" />
      </geometry>
      <material name="">
        <color rgba="0.898039215686275 0.917647058823529 0.929411764705882 1" />
      </material>
    </visual>
    <collision>
      <origin xyz="0.00 -0.0195 0.00" rpy="1.5708 0 0" />
      <geometry>
        <cylinder radius="0.064" length="0.03" />
      </geometry>
    </collision>
    <collision>
      <origin xyz="-0.125 -0.02059 -0.01001" rpy="0 -0.13 0" />
      <geometry>
        <box size="0.18 0.03 0.06" />
      </geometry>
    </collision>
    <collision>
      <origin xyz="-0.2485 -0.032 -0.0135" rpy="1.5708 0 0" />
      <geometry>
        <cylinder radius="0.0655" length="0.056" />
      </geometry>
    </collision>
  </link>
  <joint name="fr_thigh_joint" type="revolute">
    <origin xyz="0.078 -0.0795 0" rpy="0 0 0" />
    <parent link="fr_hip_Link" />
    <child link="fr_thigh_Link" />
    <axis xyz="0 1 0" />
    <limit lower="-3.14" upper="0" effort="0" velocity="0" />
  </joint>
  <link name="fr_calf_Link">
    <inertial>
      <origin xyz="0.17266 -0.02895 0.04224" rpy="0 0 0" />
      <mass value="1.89384" />
      <inertia ixx="0.00844" ixy="0.01065" ixz="-0.01871" iyy="0.08429" iyz="0.00261" izz="0.08034" />
    </inertial>
    <visual>
      <origin xyz="0 0 0" rpy="0 0 0" />
      <geometry>
        <mesh filename="../meshes/fr_calf_Link.STL" />
      </geometry>
      <material name="">
        <color rgba="0.898039215686275 0.917647058823529 0.929411764705882 1" />
      </material>
    </visual>
    <collision>
      <origin xyz="0.00 -0.02653 0.000" rpy="1.5708 0 0" />
      <geometry>
        <cylinder radius="0.0635" length="0.03" />
      </geometry>
    </collision>
    <collision>
      <origin xyz="0.140 -0.02903 0.03050" rpy="0 -0.2618 0" />
      <geometry>
        <box size="0.18 0.04 0.045" />
      </geometry>
    </collision>
    <collision>
      <origin xyz="0.249 -0.02903 0.05310" rpy="1.5708 0 0" />
      <geometry>
        <cylinder radius="0.06" length="0.055" />
      </geometry>
    </collision>
  </link>
  <joint name="fr_calf_joint" type="revolute">
    <origin xyz="-0.24954 -0.057 -0.01515" rpy="0 0 0" />
    <parent link="fr_thigh_Link" />
    <child link="fr_calf_Link" />
    <axis xyz="0 1 0" />
    <limit lower="0" upper="3.14" effort="0" velocity="0" />
  </joint>
  <link name="fr_foot_Link">
    <inertial>
      <origin xyz="0.00146 -0.01336 -0.00634" rpy="0 0 0" />
      <mass value="0.32377" />
      <inertia ixx="0.00072" ixy="0.00001" ixz="0.00000" iyy="0.00122" iyz="-0.00003" izz="0.00071" />
    </inertial>
    <visual>
      <origin xyz="0 0 0" rpy="0 0 0" />
      <geometry>
        <mesh filename="../meshes/fr_foot_Link.STL" />
      </geometry>
      <material name="">
        <color rgba="0.898039215686275 0.917647058823529 0.929411764705882 1" />
      </material>
    </visual>
    <collision>
      <origin xyz="0 -0.01631 0" rpy="1.5708 0 0" />
      <geometry>
        <cylinder radius="0.12" length="0.05617" />
      </geometry>
    </collision>
  </link>
  <joint name="fr_foot_joint" type="continuous">
    <origin xyz="0.24443 -0.061 0.0525" rpy="0 0 0" />
    <parent link="fr_calf_Link" />
    <child link="fr_foot_Link" />
    <axis xyz="0 1 0" />
    <limit lower="0" upper="0" effort="0" velocity="0" />
  </joint>

  <link name="fl_hip_Link">
    <inertial>
      <origin xyz="0.06964 0.04836 -0.00073" rpy="0 0 0" />
      <mass value="1.78126" />
      <inertia ixx="0.00712" ixy="-0.00663" ixz="0.00012" iyy="0.01306" iyz="0.00007" izz="0.01637" />
    </inertial>
    <visual>
      <origin xyz="0 0 0" rpy="0 0 0" />
      <geometry>
        <mesh filename="../meshes/fl_hip_Link.STL" />
      </geometry>
      <material name="">
        <color rgba="0.898039215686275 0.917647058823529 0.929411764705882 1" />
      </material>
    </visual>
    <collision>
      <origin xyz="0.07752 0.05564 0.00083" rpy="1.5708 0 0" />
      <geometry>
        <cylinder radius="0.06" length="0.048" />
      </geometry>
    </collision>
  </link>
  <joint name="fl_hip_joint" type="revolute">
    <origin xyz="0.2395 0.065 0.08065" rpy="0 0 0" />
    <parent link="base_link" />
    <child link="fl_hip_Link" />
    <axis xyz="-1 0 0" />
    <limit lower="-0.41" upper="0.41" effort="0" velocity="0" />
  </joint>
  <link name="fl_thigh_Link">
    <inertial>
      <origin xyz="-0.19484 0.02855 -0.01176" rpy="0 0 0" />
      <mass value="2.40982" />
      <inertia ixx="0.00584" ixy="0.01503" ixz="-0.00692" iyy="0.12002" iyz="0.00093" izz="0.11966" />
    </inertial>
    <visual>
      <origin xyz="0 0 0" rpy="0 0 0" />
      <geometry>
        <mesh filename="../meshes/fl_thigh_Link.STL" />
      </geometry>
      <material name="">
        <color rgba="0.898039215686275 0.917647058823529 0.929411764705882 1" />
      </material>
    </visual>
    <collision>
      <origin xyz="0.00 0.0195 0.00" rpy="1.5708 0 0" />
      <geometry>
        <cylinder radius="0.064" length="0.03" />
      </geometry>
    </collision>
    <collision>
      <origin xyz="-0.125 0.02059 -0.01001" rpy="0 -0.13 0" />
      <geometry>
        <box size="0.18 0.03 0.06" />
      </geometry>
    </collision>
    <collision>
      <origin xyz="-0.2485 0.032 -0.0135" rpy="1.5708 0 0" />
      <geometry>
        <cylinder radius="0.0655" length="0.056" />
      </geometry>
    </collision>
  </link>
  <joint name="fl_thigh_joint" type="revolute">
    <origin xyz="0.078 0.0795 0" rpy="0 0 0" />
    <parent link="fl_hip_Link" />
    <child link="fl_thigh_Link" />
    <axis xyz="0 -1 0" />
    <limit lower="0" upper="3.14" effort="0" velocity="0" />
  </joint>
  <link name="fl_calf_Link">
    <inertial>
      <origin xyz="0.17384 0.02895 0.03735" rpy="0 0 0" />
      <mass value="1.89384" />
      <inertia ixx="0.00744" ixy="-0.01072" ixz="-0.01666" iyy="0.08434" iyz="-0.00231" izz="0.08139" />
    </inertial>
    <visual>
      <origin xyz="0 0 0" rpy="0 0 0" />
      <geometry>
        <mesh filename="../meshes/fl_calf_Link.STL" />
      </geometry>
      <material name="">
        <color rgba="0.898039215686275 0.917647058823529 0.929411764705882 1" />
      </material>
    </visual>
    <collision>
      <origin xyz="0.00 0.02653 0.000" rpy="1.5708 0 0" />
      <geometry>
        <cylinder radius="0.0635" length="0.03" />
      </geometry>
    </collision>
    <collision>
      <origin xyz="0.140 0.02903 0.03050" rpy="0 -0.2618 0" />
      <geometry>
        <box size="0.18 0.04 0.045" />
      </geometry>
    </collision>
    <collision>
      <origin xyz="0.249 0.02903 0.05310" rpy="1.5708 0 0" />
      <geometry>
        <cylinder radius="0.06" length="0.055" />
      </geometry>
    </collision>
  </link>
  <joint name="fl_calf_joint" type="revolute">
    <origin xyz="-0.24954 0.057 -0.01515" rpy="0 0 0" />
    <parent link="fl_thigh_Link" />
    <child link="fl_calf_Link" />
    <axis xyz="0 -1 0" />
    <limit lower="-3.14" upper="0" effort="0" velocity="0" />
  </joint>
  <link name="fl_foot_Link">
    <inertial>
      <origin xyz="0.00000 0.01336 0.00000" rpy="0 0 0" />
      <mass value="0.32377" />
      <inertia ixx="0.00071" ixy="0.00000" ixz="0.00000" iyy="0.00121" iyz="0.00000" izz="0.00071" />
    </inertial>
    <visual>
      <origin xyz="0 0 0" rpy="0 0 0" />
      <geometry>
        <mesh filename="../meshes/fl_foot_Link.STL" />
      </geometry>
      <material name="">
        <color rgba="0.898039215686275 0.917647058823529 0.929411764705882 1" />
      </material>
    </visual>
    <collision>
      <origin xyz="0 0.01631 0" rpy="1.5708 0 0" />
      <geometry>
        <cylinder radius="0.12" length="0.05617" />
      </geometry>
    </collision>
  </link>
  <joint name="fl_foot_joint" type="continuous">
    <origin xyz="0.24443 0.061 0.0525" rpy="0 0 0" />
    <parent link="fl_calf_Link" />
    <child link="fl_foot_Link" />
    <axis xyz="0 -1 0" />
    <limit lower="0" upper="0" effort="0" velocity="0" />
  </joint>

  <link name="rr_hip_Link">
    <inertial>
      <origin xyz="-0.06964 -0.04836 -0.00073" rpy="0 0 0" />
      <mass value="1.78126" />
      <inertia ixx="0.00712" ixy="-0.00663" ixz="-0.00012" iyy="0.01306" iyz="-0.00007" izz="0.01637" />
    </inertial>
    <visual>
      <origin xyz="0 0 0" rpy="0 0 0" />
      <geometry>
        <mesh filename="../meshes/rr_hip_Link.STL" />
      </geometry>
      <material name="">
        <color rgba="0.898039215686275 0.917647058823529 0.929411764705882 1" />
      </material>
    </visual>
    <collision>
      <origin xyz="-0.07752 -0.05564 0.00083" rpy="1.5708 0 0" />
      <geometry>
        <cylinder radius="0.06" length="0.048" />
      </geometry>
    </collision>
  </link>
  <joint name="rr_hip_joint" type="revolute">
    <origin xyz="-0.2395 -0.065 0.08065" rpy="0 0 0" />
    <parent link="base_link" />
    <child link="rr_hip_Link" />
    <axis xyz="1 0 0" />
    <limit lower="-0.41" upper="0.41" effort="0" velocity="0" />
  </joint>
  <link name="rr_thigh_Link">
    <inertial>
      <origin xyz="0.19473 -0.02855 -0.01335" rpy="0 0 0" />
      <mass value="2.40982" />
      <inertia ixx="0.00596" ixy="0.01503" ixz="0.00785" iyy="0.12002" iyz="-0.00105" izz="0.11954" />
    </inertial>
    <visual>
      <origin xyz="0 0 0" rpy="0 0 0" />
      <geometry>
        <mesh filename="../meshes/rr_thigh_Link.STL" />
      </geometry>
      <material name="">
        <color rgba="0.898039215686275 0.917647058823529 0.929411764705882 1" />
      </material>
    </visual>
    <collision>
      <origin xyz="0.00 -0.0195 0.00" rpy="1.5708 0 0" />
      <geometry>
        <cylinder radius="0.064" length="0.03" />
      </geometry>
    </collision>
    <collision>
      <origin xyz="0.125 -0.02059 -0.01001" rpy="0 0.13 0" />
      <geometry>
        <box size="0.18 0.03 0.06" />
      </geometry>
    </collision>
    <collision>
      <origin xyz="0.2485 -0.032 -0.0135" rpy="1.5708 0 0" />
      <geometry>
        <cylinder radius="0.0655" length="0.056" />
      </geometry>
    </collision>
  </link>
  <joint name="rr_thigh_joint" type="revolute">
    <origin xyz="-0.078 -0.0795 0" rpy="0 0 0" />
    <parent link="rr_hip_Link" />
    <child link="rr_thigh_Link" />
    <axis xyz="0 1 0" />
    <limit lower="0" upper="3.14" effort="0" velocity="0" />
  </joint>
  <link name="rr_calf_Link">
    <inertial>
      <origin xyz="-0.17353 -0.02895 0.03877" rpy="0 0 0" />
      <mass value="1.89384" />
      <inertia ixx="0.00772" ixy="-0.01070" ixz="0.01726" iyy="0.08434" iyz="0.00240" izz="0.08111" />
    </inertial>
    <visual>
      <origin xyz="0 0 0" rpy="0 0 0" />
      <geometry>
        <mesh filename="../meshes/rr_calf_Link.STL" />
      </geometry>
      <material name="">
        <color rgba="0.898039215686275 0.917647058823529 0.929411764705882 1" />
      </material>
    </visual>
    <collision>
      <origin xyz="0.00 -0.02653 0.000" rpy="1.5708 0 0" />
      <geometry>
        <cylinder radius="0.0635" length="0.03" />
      </geometry>
    </collision>
    <collision>
      <origin xyz="-0.140 -0.02903 0.03050" rpy="0 0.2618 0" />
      <geometry>
        <box size="0.18 0.04 0.045" />
      </geometry>
    </collision>
    <collision>
      <origin xyz="-0.249 -0.02903 0.05310" rpy="1.5708 0 0" />
      <geometry>
        <cylinder radius="0.06" length="0.055" />
      </geometry>
    </collision>
  </link>
  <joint name="rr_calf_joint" type="revolute">
    <origin xyz="0.24954 -0.057 -0.01515" rpy="0 0 0" />
    <parent link="rr_thigh_Link" />
    <child link="rr_calf_Link" />
    <axis xyz="0 1 0" />
    <limit lower="-6.28" upper="0" effort="0" velocity="0" />
  </joint>
  <link name="rr_foot_Link">
    <inertial>
      <origin xyz="0.00000 -0.01336 0.00000" rpy="0 0 0" />
      <mass value="0.32377" />
      <inertia ixx="0.00071" ixy="0.00000" ixz="0.00000" iyy="0.00121" iyz="0.00000" izz="0.00071" />
    </inertial>
    <visual>
      <origin xyz="0 0 0" rpy="0 0 0" />
      <geometry>
        <mesh filename="../meshes/rr_foot_Link.STL" />
      </geometry>
      <material name="">
        <color rgba="0.898039215686275 0.917647058823529 0.929411764705882 1" />
      </material>
    </visual>
    <collision>
      <origin xyz="0 -0.01631 0" rpy="1.5708 0 0" />
      <geometry>
        <cylinder radius="0.12" length="0.05617" />
      </geometry>
    </collision>
  </link>
  <joint name="rr_foot_joint" type="continuous">
    <origin xyz="-0.24443 -0.061 0.0525" rpy="0 0 0" />
    <parent link="rr_calf_Link" />
    <child link="rr_foot_Link" />
    <axis xyz="0 1 0" />
    <limit lower="0" upper="0" effort="0" velocity="0" />
  </joint>

  <link name="rl_hip_Link">
    <inertial>
      <origin xyz="-0.06960 0.04836 0.00075" rpy="0 0 0" />
      <mass value="1.78126" />
      <inertia ixx="0.00712" ixy="0.00662" ixz="0.00012" iyy="0.01305" iyz="-0.00007" izz="0.01635" />
    </inertial>
    <visual>
      <origin xyz="0 0 0" rpy="0 0 0" />
      <geometry>
        <mesh filename="../meshes/rl_hip_Link.STL" />
      </geometry>
      <material name="">
        <color rgba="0.898039215686275 0.917647058823529 0.929411764705882 1" />
      </material>
    </visual>
    <collision>
      <origin xyz="-0.07752 0.05564 0.00083" rpy="1.5708 0 0" />
      <geometry>
        <cylinder radius="0.06" length="0.048" />
      </geometry>
    </collision>
  </link>
  <joint name="rl_hip_joint" type="revolute">
    <origin xyz="-0.2395 0.065 0.08065" rpy="0 0 0" />
    <parent link="base_link" />
    <child link="rl_hip_Link" />
    <axis xyz="1 0 0" />
    <limit lower="-0.41" upper="0.41" effort="0" velocity="0" />
  </joint>
  <link name="rl_thigh_Link">
    <inertial>
      <origin xyz="0.19519 0.02855 -0.01131" rpy="0 0 0" />
      <mass value="2.40982" />
      <inertia ixx="0.00576" ixy="-0.01508" ixz="0.00665" iyy="0.12042" iyz="0.00087" izz="0.12013" />
    </inertial>
    <visual>
      <origin xyz="0 0 0" rpy="0 0 0" />
      <geometry>
        <mesh filename="../meshes/rl_thigh_Link.STL" />
      </geometry>
      <material name="">
        <color rgba="0.898039215686275 0.917647058823529 0.929411764705882 1" />
      </material>
    </visual>
    <collision>
      <origin xyz="0.00 0.0195 0.00" rpy="1.5708 0 0" />
      <geometry>
        <cylinder radius="0.064" length="0.03" />
      </geometry>
    </collision>
    <collision>
      <origin xyz="0.125 0.02059 -0.01001" rpy="0 0.13 0" />
      <geometry>
        <box size="0.18 0.03 0.06" />
      </geometry>
    </collision>
    <collision>
      <origin xyz="0.2485 0.032 -0.0135" rpy="1.5708 0 0" />
      <geometry>
        <cylinder radius="0.0655" length="0.056" />
      </geometry>
    </collision>
  </link>
  <joint name="rl_thigh_joint" type="revolute">
    <origin xyz="-0.078 0.0795 0" rpy="0 0 0" />
    <parent link="rl_hip_Link" />
    <child link="rl_thigh_Link" />
    <axis xyz="0 -1 0" />
    <limit lower="-3.14" upper="0" effort="0" velocity="0" />
  </joint>
  <link name="rl_calf_Link">
    <inertial>
      <origin xyz="-0.17385 0.02895 0.03733" rpy="0 0 0" />
      <mass value="1.89384" />
      <inertia ixx="0.00744" ixy="0.01073" ixz="0.01665" iyy="0.08434" iyz="-0.00230" izz="0.08139" />
    </inertial>
    <visual>
      <origin xyz="0 0 0" rpy="0 0 0" />
      <geometry>
        <mesh filename="../meshes/rl_calf_Link.STL" />
      </geometry>
      <material name="">
        <color rgba="0.898039215686275 0.917647058823529 0.929411764705882 1" />
      </material>
    </visual>
    <collision>
      <origin xyz="0.00 0.02653 0.000" rpy="1.5708 0 0" />
      <geometry>
        <cylinder radius="0.0635" length="0.03" />
      </geometry>
    </collision>
    <collision>
      <origin xyz="-0.140 0.02903 0.03050" rpy="0 0.2618 0" />
      <geometry>
        <box size="0.18 0.04 0.045" />
      </geometry>
    </collision>
    <collision>
      <origin xyz="-0.249 0.02903 0.05310" rpy="1.5708 0 0" />
      <geometry>
        <cylinder radius="0.06" length="0.055" />
      </geometry>
    </collision>
  </link>
  <joint name="rl_calf_joint" type="revolute">
    <origin xyz="0.24954 0.057 -0.01515" rpy="0 0 0" />
    <parent link="rl_thigh_Link" />
    <child link="rl_calf_Link" />
    <axis xyz="0 -1 0" />
    <limit lower="0" upper="6.28" effort="0" velocity="0" />
  </joint>
  <link name="rl_foot_Link">
    <inertial>
      <origin xyz="0.00000 0.01336 0.00000" rpy="0 0 0" />
      <mass value="0.32377" />
      <inertia ixx="0.00071" ixy="0.00000" ixz="0.00000" iyy="0.00121" iyz="0.00000" izz="0.00071" />
    </inertial>
    <visual>
      <origin xyz="0 0 0" rpy="0 0 0" />
      <geometry>
        <mesh filename="../meshes/rl_foot_Link.STL" />
      </geometry>
      <material name="">
        <color rgba="0.898039215686275 0.917647058823529 0.929411764705882 1" />
      </material>
    </visual>
    <collision>
      <origin xyz="0 0.01631 0" rpy="1.5708 0 0" />
      <geometry>
        <cylinder radius="0.12" length="0.05617" />
      </geometry>
    </collision>
  </link>
  <joint name="rl_foot_joint" type="continuous">
    <origin xyz="-0.24443 0.061 0.0525" rpy="0 0 0" />
    <parent link="rl_calf_Link" />
    <child link="rl_foot_Link" />
    <axis xyz="0 -1 0" />
    <limit lower="0" upper="0" effort="0" velocity="0" />
  </joint>

  <link name="lidar1_Link">
    <inertial>
      <origin xyz="-0.00115 -0.00002 -0.00940" rpy="0 0 0" />
      <mass value="0.05259" />
      <inertia ixx="0.00004" ixy="0.00000" ixz="0.00000" iyy="0.00004" iyz="0.00000" izz="0.00002" />
    </inertial>
    <visual>
      <origin xyz="0 0 0" rpy="0 0 0" />
      <geometry>
        <mesh filename="../meshes/lidar1_Link.STL" />
      </geometry>
      <material name="">
        <color rgba="0.898039215686275 0.917647058823529 0.929411764705882 1" />
      </material>
    </visual>
  </link>
  <joint name="lidar1_joint" type="fixed">
    <origin xyz="0.39288 0.00040465 0.057801" rpy="-3.1416 -0.7854 0" />
    <parent link="base_link" />
    <child link="lidar1_Link" />
    <axis xyz="0 0 0" />
  </joint>

  <link name="camera1_Link">
    <inertial>
      <origin xyz="-0.00092 0.00008 -0.01518" rpy="0 0 0" />
      <mass value="0.02011" />
      <inertia ixx="0.00001" ixy="0.00000" ixz="0.00000" iyy="0.00002" iyz="0.00000" izz="0.00001" />
    </inertial>
    <visual>
      <origin xyz="0 0 0" rpy="0 0 0" />
      <geometry>
        <mesh filename="../meshes/camera1_Link.STL" />
      </geometry>
      <material name="">
        <color rgba="0.898039215686275 0.917647058823529 0.929411764705882 1" />
      </material>
    </visual>
  </link>
  <joint name="camera1_joint" type="fixed">
    <origin xyz="0.41351 -0.00018636 0.11372" rpy="-1.9199 0 -1.5708" />
    <parent link="base_link" />
    <child link="camera1_Link" />
    <axis xyz="0 0 0" />
  </joint>

  <link name="lidar2_Link">
    <inertial>
      <origin xyz="-0.00115 -0.00002 -0.00940" rpy="0 0 0" />
      <mass value="0.05259" />
      <inertia ixx="0.00004" ixy="0.00000" ixz="0.00000" iyy="0.00004" iyz="0.00000" izz="0.00002" />
    </inertial>
    <visual>
      <origin xyz="0 0 0" rpy="0 0 0" />
      <geometry>
        <mesh filename="../meshes/lidar2_Link.STL" />
      </geometry>
      <material name="">
        <color rgba="0.898039215686275 0.917647058823529 0.929411764705882 1" />
      </material>
    </visual>
    <collision>
      <origin xyz="0.0 0.0 -0.00944981724023819" rpy="0 0 0" />
      <geometry>
        <box size="0.0768 0.0768 0.0801" />
      </geometry>
    </collision>
  </link>
  <joint name="lidar2_joint" type="fixed">
    <origin xyz="-0.29638 -0.0012453 0.19435" rpy="0 0 3.1416" />
    <parent link="base_link" />
    <child link="lidar2_Link" />
    <axis xyz="0 0 0" />
  </joint>

  <link name="camera2_Link">
    <inertial>
      <origin xyz="-0.00092 -0.00012 -0.01518" rpy="0 0 0" />
      <mass value="0.02011" />
      <inertia ixx="0.00001" ixy="0.00000" ixz="0.00000" iyy="0.00002" iyz="0.00000" izz="0.00001" />
    </inertial>
    <visual>
      <origin xyz="0 0 0" rpy="0 0 0" />
      <geometry>
        <mesh filename="../meshes/camera2_Link.STL" />
      </geometry>
      <material name="">
        <color rgba="0.898039215686275 0.917647058823529 0.929411764705882 1" />
      </material>
    </visual>
  </link>
  <joint name="camera2_joint" type="fixed">
    <origin xyz="-0.41791 -0.0012432 0.078009" rpy="1.5708 1.5708 -1.5838" />
    <parent link="base_link" />
    <child link="camera2_Link" />
  </joint>
</robot>